<?xml version="1.0"?>
<robot xmlns:xacro="http://www.ros.org/wiki/xacro">

  <xacro:property name="T200_body_mesh" value="file://$(find pontus_description)/models/pontus/meshes/T200_body.STL"/>
  <xacro:property name="T200_prop_mesh" value="file://$(find pontus_description)/models/pontus/meshes/T200_prop.STL"/>

  <xacro:macro name="T200_macro" params="thruster_id *origin">

    <link name="thruster_${thruster_id}">
      <visual>
        <geometry>
          <mesh filename="${T200_body_mesh}"/>
        </geometry>
        <material name="Black">
          <color rgba="0.0 0.0 0.0 1.0"/>
        </material>
      </visual>
    </link>

    <joint name="thruster_joint_${thruster_id}" type="fixed">
      <xacro:insert_block name="origin"/>
      <parent link="base_link"/>
      <child link="thruster_${thruster_id}"/>
      <axis xyz="1 0 0"/>
    </joint>

    <link name="propeller_${thruster_id}">

      <!-- The inertial values need to be reasonable or gazebo will crash -->
      <inertial>
        <mass value="0.01" />
        <inertia ixx="0.001" ixy="0.0" ixz="0.0"
                 iyy="0.001" iyz="0.0" izz="0.001" />
      </inertial>

      <visual>
        <geometry>
          <mesh filename="${T200_prop_mesh}"/>
        </geometry>
        <material name="Light Blue">
          <color rgba="0.26 0.46 0.68 1.0"/>
        </material>
      </visual>
    </link>

    <joint name="prop_joint_${thruster_id}" type="continuous">
      <parent link="thruster_${thruster_id}"/>
      <child link="propeller_${thruster_id}"/>
      <axis xyz="0 0 1"/>
    </joint>

    <!-- T200 information:
	    Max Thrust: 51.5 N
	    Max Rotation Rate: 370 Rad/s
	    Thruster Coefficient: .0109 1/Rad^2
    -->

    <gazebo>
      <plugin
        filename="gz-sim-thruster-system"
        name="gz::sim::systems::Thruster">
        <joint_name>prop_joint_${thruster_id}</joint_name>
        <thrust_coefficient>0.0109</thrust_coefficient>
        <fluid_density>1025</fluid_density>
        <propeller_diameter>0.076</propeller_diameter>
        <velocity_control>true</velocity_control>
      </plugin>
    </gazebo>
  </xacro:macro>

</robot>
